Workbook

Sheet Sprint Tracker
A1: Sprint List
A2: Objective : File ini digunakan oleh CI dan Deployment untuk mentracking List Sprint sepanjang tahun 2025
A3: User yang memiliki akses untuk edit adalah : Tim Deployment & CI
A4: Sprint 7, need tobe check by tim CI
O5: SPRINT 8
C6: CI Team | G6: CI Team | O6: 45907 | P6: 45920 | Q6: 45927 | R6: 45929 | S6: 45958 | V6: CI Team | W6: CI Team | X6: CI Team
A7: No | B7: Platform (Aplikasi) | C7: Dependency | D7: Background | E7: Objective | F7: Description | G7: Product Manager | H7: Requestor | I7: Chanel | J7: Expected Deployed | K7: Sprint | L7: Sprint Carry Over | M7: Story Point (if available) | N7: Update 08/28 | O7: Update 1 | P7: Update 2 | Q7: Update 3 | R7: Update 4 | S7: Update 5 | T7: Update 6 | U7: Update 7 | V7: PRD | W7: JIRA Ticket | X7: Picked Up
A8: 1 | B8: AMO | D8: QR code phase 2 (adding button to top up canvassing during pengiriman CITA di AMO offline) | E8: QR code phase 2 (adding button to top up canvassing during pengiriman CITA di AMO offline) | F8: QR code phase 2 (adding button to top up canvassing during pengiriman CITA di AMO offline) | G8: Marcha | H8: Duta | J8: 45870 | K8: Sprint 6 | O8: Done
A9: 2 | B9: AMO | D9: Canvassing = Product assortment / carousel untuk focused product | E9: Canvassing = Product assortment / carousel untuk focused product | F9: Canvassing = Product assortment / carousel untuk focused product follow B2B | G9: Marcha | H9: Duta | J9: 45870 | K9: Sprint 6 | O9: Done
A10: 3 | B10: AMO | D10: SKU reminder untuk focused product sebelum dilakukan payment | E10: SKU reminder untuk focused product sebelum dilakukan payment | F10: SKU reminder untuk focused product sebelum dilakukan payment (Re-offering) | G10: Marcha | H10: Duta | J10: 45870 | K10: Sprint 6 | O10: Done
A11: 4 | B11: AMO | D11: Mendapatkan progress achievement PG (Unique Call, Volume canvass & CITA) dari PBI Reporting AMO | E11: Mendapatkan progress achievement PG (Unique Call, Volume canvass & CITA) dari PBI Reporting AMO | F11: Mendapatkan progress achievement PG (Unique Call, Volume canvass & CITA) dari PBI Reporting AMO | G11: Marcha | H11: Duta | J11: 45870 | K11: Sprint 6 | O11: Done
A12: 5 | B12: AMO | D12: Add tab "Laporan" untuk menunjukan progress achievement PG (Unique Call, Volume canvass & CITA) | E12: Add tab "Laporan" untuk menunjukan progress achievement PG (Unique Call, Volume canvass & CITA) | F12: Add tab "Laporan" untuk menunjukan progress achievement PG (Unique Call, Volume canvass & CITA) | G12: Marcha | H12: Duta | J12: 45870 | K12: Sprint 6 | O12: Done
A13: 6 | B13: AYO Principal | D13: Elevate Automation | E13: Elevate - Data Entry | F13: Capability untuk user bisa melakukan WO atau guideline submission | G13: Ariph | H13: Nika | J13: 45930
A14: 7 | B14: AYO Principal | D14: Elevate Automation | E14: Elevate - Email generator | F14: Capability elevate untuk generate email ke zone sehubungan dengan WO/guideline yang diinputkan di Elevate | G14: Ariph | H14: Nika | J14: 45930 | K14: Sprint 8
A15: 8 | B15: AYO Principal | D15: Elevate Automation | E15: Elevate - Cycle calendar | F15: Capability untuk show dan filter WO atau guideline yang impact ke waktu week tertentu | G15: Ariph | H15: Nika | J15: 45930
A16: 9 | B16: Control Tower | D16: Seamless data upload | E16: CT Update Schedulling and rework data entry template | F16: Flexybility update data in CT by add feature schedule | G16: Ariph | H16: Sri P | J16: 45930 | K16: Sprint 7 | L16: Sprint 8 | N16: carry over to the next sprint
A17: 10 | B17: AMO | D17: Canvassing | E17: Fitur Scan QR pada mode Canvassing | F17: Edit text Kunjungan Non Downline menjadi "Mulai Kunjungan", direct page to fitur Scan QR dan akan ter-mapping ke customer registered HMS as map to RE | G17: Marcha | H17: Duta | J17: 45930 | K17: Sprint 7 | N17: covered in sprint 7
A18: 11 | B18: AMO plus | D18: Filter type outlet di maps | E18: Filter type outlet di maps | F18: Selecting toko yang tampil di peta pada AMO | G18: Maulana | H18: Duta | J18: 45930 | K18: Sprint 7
A19: 12 | B19: AMO Plus | D19: Search downline PG | E19: Search downline PG | F19: Fitur search downline salesman/mitra di AMO+ (seperti di AMO Existing) | G19: Maulana | H19: Duta | J19: 45930 | K19: Sprint 7
A20: 13 | B20: AMO Plus | D20: Remaining stock product PG | E20: Remaining stock product PG | F20: Info sisa stok yang dibawa PG di page transaksi | G20: Maulana | H20: Duta | J20: 45930 | K20: Sprint 7
A21: 14 | B21: AMO Plus | D21: Price product di page transaksi | E21: Price product di page transaksi | F21: Info price product / SKU di halaman transaksi | G21: Maulana | H21: Duta | J21: 45930 | K21: Sprint 7
A22: 15 | B22: AMO Plus | D22: Reconciliation report | E22: Reconciliation report | F22: Menggabungkan LPU dan BPPB pada AMO | G22: Maulana | H22: Duta | J22: 45930 | K22: Sprint 7
A23: 16 | B23: AYO Mitra Plus | D23: Manual assign by PG khususnya jika ada PG yg tidak masuk | E23: Manual assign by PG khususnya jika ada PG yg tidak masuk | F23: Manual assign by PG khususnya jika ada PG yg tidak masuk | G23: Maulana | H23: Sri P | J23: 45930 | K23: Sprint 7
A24: 17 | B24: AYO Mitra Plus | D24: Grouping order by PG di hari H-1 | E24: Grouping order by PG di hari H-1 | F24: Grouping order by PG di hari H | G24: Maulana | H24: Sri P | J24: 45930 | K24: Sprint 7
A25: 18 | B25: AYO Mitra Plus | D25: Mitra tetap dapat melakukan cluster, meskipun masih ada pesanan dalam pengiriman | E25: Mitra tetap dapat melakukan cluster, meskipun masih ada pesanan dalam pengiriman | F25: Mitra tetap dapat melakukan proses pesanan, ketika ada pesanan baru | G25: Maulana | H25: Sri P | J25: 45930 | K25: Sprint 7
A26: 19 | B26: AYO Mitra Plus | D26: Fixing miss cluster | E26: Fixing miss cluster | F26: Fixing miss cluster | G26: Maulana | H26: Sri P | J26: 45930 | K26: Sprint 7
A27: 20 | B27: AYO Mitra Plus | D27: Simply Initial load reccomendation | E27: Simply Initial load reccomendation | F27: Simply Initial load reccomendation | G27: Maulana | H27: Sri P | J27: 45930 | K27: Sprint 7
A28: 21 | B28: MyHero | D28: Hygiene document | E28: LPU | F28: Saat ini yang muncul ketika cetak LPU hanyalah tanggal cetak, bukan tanggal journeynya Add 1 field for tanggal journey | G28: Melissa Tio | H28: Nika | J28: 45930 | K28: Sprint 7
A29: 22 | B29: MyHero | D29: Multicategory document | E29: BPPB, Add load | F29: On top of kode barang, penambahan Prod name (masking) di BPPB untuk FMCG | G29: Melissa Tio | H29: Nika | J29: 45930 | K29: Sprint 7
A30: 23 | B30: MyHero | D30: Multicategory document | E30: BPPB, Add load | F30: Printed doc DN after jourgen dan input initial load by back end | G30: Melissa Tio | H30: Nika | J30: 45930 | K30: Sprint 7
A31: 24 | B31: CITA | D31: Detect distinct SKU and pack quantity inside paket produk | E31: Detect distinct SKU and pack quantity inside paket produk | F31: To be able to detect quantity of packs inside Paket Produk | G31: Nessia | H31: Sri/CI | J31: 45930 | K31: Sprint 7 | N31: covered in sprint 7
A32: 25 | B32: CITA | D32: Category Standardization | E32: Category Standardization | F32: To standardize category chip shown on CITA to refer to category on Product Principal instead of referring on "subfamily" column on produk supplier menu on Control Tower | G32: Nessia | H32: Sri/CI | J32: 45930 | K32: Sprint 7 | N32: covered in sprint 7
A33: 26 | B33: AYO Kasir | D33: Eliminate double transaction happened in AYO due unresponsive Payment gateway | E33: [CDE-25950] AYO Kasir - Limit transaction when FF spam selesaikan pesanan button more than 1x | G33: Marcha | H33: Ida/Adnan | J33: 45930 | K33: Sprint 7 | N33: deployed, 13 aug
A34: 27 | B34: AYO Kasir | D34: Integrate ORF request & process in AYO Kasir | E34: ORF | F34: ORF submission form & process in AYO Kasir to eliminate manual form & manual tracking | G34: Marcha | H34: Ida/Adnan | J34: 45930 | K34: Sprint 7 | N34: covered in sprint 7 ( tp butuh lintas sprint)
A35: 28 | B35: AYO Kasir | D35: Provide inventory data access to AYO Kasir Admin | E35: Stock Count & Stock Adjusment | F35: Laporan inventory harian per toko, per staff, per SKU untuk membantu daily stock take process | G35: Marcha | H35: Ida/Adnan | J35: 45930 | K35: Sprint 7 | N35: covered in sprint 7 ( tp butuh lintas sprint)
A36: 29 | B36: AYO Kasir | D36: Support perpindahan stock antar toko (pemerataan Limited stock & LOGD) | E36: Stock Transfer Store to Store | F36: Stock dapat dipindahkan antar toko (dan antar SLOC) melalui fitur stock movement (beserta history nya) yang dapat di tracking, termasuk dengan penyesuaian di SAP nya | G36: Marcha | H36: Ida/Adnan | J36: 45930 | K36: Sprint 7 | N36: covered in sprint 7 ( tp butuh lintas sprint)
A37: 30 | B37: AYO Kasir | D37: Support loyalty/miles program di IQOS Partne dan allow customization | E37: IP Miles, VAP, Delivery Partner Program | F37: IP memiliki beberapa loyalty toolbox option yang bisa dipilih oleh masing-masing mereka, menyesuaikan dengan kebutuhan bisnis | G37: Marcha | H37: Ida/Adnan | J37: 45930 | K37: Sprint 7 | N37: covered in sprint 7 ( tp butuh lintas sprint)
A38: 31 | B38: AYO Kasir | D38: Provide inventory management & tracking untuk AYO Kasir admin dalam memindahkan stock ke setiap staff | E38: Stock Transfer Admin to Staff | F38: AYO Kasir Admin memerlukan control terhadap inventory management & movement di setiap staff nya, termasuk visibility terkait stock on hand dan movement history yang bisa di track setiap saat untuk monitoring & stock audit | G38: Marcha | H38: Ida/Adnan | J38: 45930 | K38: Sprint 7 | N38: covered in sprint 7
A39: 32 | B39: AYO Kasir | D39: Provide codentify form box for each device purchased --> link device | E39: Device Codentify Input for every device purchased in same order id | F39: Setiap device yang terdapat di dalam suatu transaksi, memerlukan input informasi ke dalam system untuk codentify untuk setiap device. Saat ini, AYO Kasir hanya | G39: Marcha | H39: Ida/Adnan | J39: 45930 | K39: Sprint 7 | N39: covered in sprint 7
A40: 33 | B40: AYO Kasir | D40: Voucher enhancement | E40: Voucher enhancement | F40: Voucher Product Limitation Adjustment | G40: Marcha | H40: Ida/Adnan | J40: 45930 | K40: Sprint 7 | N40: covered in sprint 7
...

Sheet Sprint 8  with Prio
A1: Sprint List | H1: AYO Toko | J1: (3) | K1: DTE | L1: 12
A2: Objective : File ini digunakan oleh CI dan Deployment untuk mentracking List Sprint sepanjang tahun 2025 | H2: MyHero | I2: =66 -> 66 | J2: (1) | K2: AYO Kasir | L2: 97
A3: User yang memiliki akses untuk edit adalah : Tim Deployment & CI | J3: (2) | K3: CITA | L3: 50 | M3: 10 | N3: allocate to AYO Kasir
A4: Sprint 7, need tobe check by tim CI | K4: AYO Mitra
K5: AMO | L5: 107 | O5: SPRINT 8
C6: CI Team | G6: CI Team | L6: assume 1 sprint = 10 mandays | O6: 45904 | P6: 45920 | Q6: 45927 | R6: 45929 | S6: 45958
A7: No | B7: Platform (Aplikasi) | C7: Dependency | D7: Background | E7: Objective | F7: Description | G7: Product Manager | H7: Requestor | I7: Chanel | J7: Expected Deployed | K7: Sprint | L7: Rank Prio | M7: Sprint Carry Over | N7: Update 0 8/28 | O7: Update 1 | P7: Update 2 | Q7: Update 3 | R7: Update 4 | S7: Update 5 | T7: Update 6 | U7: Update 7 | V7: JIRA | W7: Mandays
A8: 1 | B8: AMO | D8: QR code phase 2 (adding button to top up canvassing during pengiriman CITA di AMO offline) | E8: QR code phase 2 (adding button to top up canvassing during pengiriman CITA di AMO offline) | F8: QR code phase 2 (adding button to top up canvassing during pengiriman CITA di AMO offline) | G8: Marcha | H8: Duta | J8: 45870 | K8: Sprint 6 | O8: Done
A9: 2 | B9: AMO | D9: Canvassing = Product assortment / carousel untuk focused product | E9: Canvassing = Product assortment / carousel untuk focused product | F9: Canvassing = Product assortment / carousel untuk focused product follow B2B | G9: Marcha | H9: Duta | J9: 45870 | K9: Sprint 6 | O9: Done
A10: 3 | B10: AMO | D10: SKU reminder untuk focused product sebelum dilakukan payment | E10: SKU reminder untuk focused product sebelum dilakukan payment | F10: SKU reminder untuk focused product sebelum dilakukan payment (Re-offering) | G10: Marcha | H10: Duta | J10: 45870 | K10: Sprint 6 | O10: Done
A11: 4 | B11: AMO | D11: Mendapatkan progress achievement PG (Unique Call, Volume canvass & CITA) dari PBI Reporting AMO | E11: Mendapatkan progress achievement PG (Unique Call, Volume canvass & CITA) dari PBI Reporting AMO | F11: Mendapatkan progress achievement PG (Unique Call, Volume canvass & CITA) dari PBI Reporting AMO | G11: Marcha | H11: Duta | J11: 45870 | K11: Sprint 6 | O11: Done
A12: 5 | B12: AMO | D12: Add tab "Laporan" untuk menunjukan progress achievement PG (Unique Call, Volume canvass & CITA) | E12: Add tab "Laporan" untuk menunjukan progress achievement PG (Unique Call, Volume canvass & CITA) | F12: Add tab "Laporan" untuk menunjukan progress achievement PG (Unique Call, Volume canvass & CITA) | G12: Marcha | H12: Duta | J12: 45870 | K12: Sprint 6 | O12: Done
A13: 6 | B13: AYO Principal | D13: Elevate Automation | E13: Elevate - Data Entry | F13: Capability untuk user bisa melakukan WO atau guideline submission | G13: Nessia | H13: Nika | J13: 45930 | K13: Sprint 7
A14: 7 | B14: AYO Principal | D14: Elevate Automation | E14: Elevate - Email generator | F14: Capability elevate untuk generate email ke zone sehubungan dengan WO/guideline yang diinputkan di Elevate | G14: Nessia | H14: Nika | J14: 45930 | K14: Sprint 7
A15: 8 | B15: AYO Principal | D15: Elevate Automation | E15: Elevate - Cycle calendar | F15: Capability untuk show dan filter WO atau guideline yang impact ke waktu week tertentu | G15: Nessia | H15: Nika | J15: 45930 | K15: Sprint 7
A16: 9 | B16: Control Tower | D16: Seamless data upload | E16: CT Update Schedulling and rework data entry template | F16: Flexybility update data in CT by add feature schedule | G16: Nessia | H16: Sri P | J16: 45930 | K16: Sprint 7 | M16: Sprint 8 | N16: carry over to the next sprint
A17: 10 | B17: AMO | D17: Canvassing | E17: Fitur Scan QR pada mode Canvassing | F17: Edit text Kunjungan Non Downline menjadi "Mulai Kunjungan", direct page to fitur Scan QR dan akan ter-mapping ke customer registered HMS as map to RE | G17: Marcha | H17: Duta | J17: 45930 | K17: Sprint 7 | N17: covered in sprint 7
A18: 11 | B18: AMO plus | D18: Filter type outlet di maps | E18: Filter type outlet di maps | F18: Selecting toko yang tampil di peta pada AMO | G18: Maulana | H18: Duta | J18: 45930 | K18: Sprint 7
A19: 12 | B19: AMO Plus | D19: Search downline PG | E19: Search downline PG | F19: Fitur search downline salesman/mitra di AMO+ (seperti di AMO Existing) | G19: Maulana | H19: Duta | J19: 45930 | K19: Sprint 7 | N19: covered in sprint 7
A20: 13 | B20: AMO Plus | D20: Remaining stock product PG | E20: Remaining stock product PG | F20: Info sisa stok yang dibawa PG di page transaksi | G20: Maulana | H20: Duta | J20: 45930 | K20: Sprint 7 | N20: covered in sprint 7
A21: 14 | B21: AMO Plus | D21: Price product di page transaksi | E21: Price product di page transaksi | F21: Info price product / SKU di halaman transaksi | G21: Maulana | H21: Duta | J21: 45930 | K21: Sprint 7 | N21: covered in sprint 7
A22: 15 | B22: AMO Plus | D22: Reconciliation report | E22: Reconciliation report | F22: Menggabungkan LPU dan BPPB pada AMO | G22: Maulana | H22: Duta | J22: 45930 | K22: Sprint 7 | N22: covered in sprint 7
A23: 16 | B23: AYO Mitra Plus | D23: Manual assign by PG khususnya jika ada PG yg tidak masuk | E23: Manual assign by PG khususnya jika ada PG yg tidak masuk | F23: Manual assign by PG khususnya jika ada PG yg tidak masuk | G23: Maulana | H23: Sri P | J23: 45930 | K23: Sprint 7 | N23: covered in sprint 7
A24: 17 | B24: AYO Mitra Plus | D24: Grouping order by PG di hari H-1 | E24: Grouping order by PG di hari H-1 | F24: Grouping order by PG di hari H | G24: Maulana | H24: Sri P | J24: 45930 | K24: Sprint 7 | N24: covered in sprint 7
A25: 18 | B25: AYO Mitra Plus | D25: Mitra tetap dapat melakukan cluster, meskipun masih ada pesanan dalam pengiriman | E25: Mitra tetap dapat melakukan cluster, meskipun masih ada pesanan dalam pengiriman | F25: Mitra tetap dapat melakukan proses pesanan, ketika ada pesanan baru | G25: Maulana | H25: Sri P | J25: 45930 | K25: Sprint 7 | N25: covered in sprint 7
A26: 19 | B26: AYO Mitra Plus | D26: Fixing miss cluster | E26: Fixing miss cluster | F26: Fixing miss cluster | G26: Maulana | H26: Sri P | J26: 45930 | K26: Sprint 7 | N26: covered in sprint 7
A27: 20 | B27: AYO Mitra Plus | D27: Simply Initial load reccomendation | E27: Simply Initial load reccomendation | F27: Simply Initial load reccomendation | G27: Maulana | H27: Sri P | J27: 45930 | K27: Sprint 7 | N27: covered in sprint 7
A28: 21 | B28: MyHero | D28: Hygiene document | E28: LPU | F28: Saat ini yang muncul ketika cetak LPU hanyalah tanggal cetak, bukan tanggal journeynya Add 1 field for tanggal journey | G28: Hadi Pram | H28: Nika | J28: 45930 | K28: Sprint 7
A29: 22 | B29: MyHero | D29: Multicategory document | E29: BPPB, Add load | F29: On top of kode barang, penambahan Prod name (masking) di BPPB untuk FMCG | G29: Hadi Pram | H29: Nika | J29: 45930 | K29: Sprint 7
A30: 23 | B30: MyHero | D30: Multicategory document | E30: BPPB, Add load | F30: Printed doc DN after jourgen dan input initial load by back end | G30: Hadi Pram | H30: Nika | J30: 45930 | K30: Sprint 7
A31: 24 | B31: CITA | D31: Detect distinct SKU and pack quantity inside paket produk | E31: Detect distinct SKU and pack quantity inside paket produk | F31: To be able to detect quantity of packs inside Paket Produk | G31: Nessia | H31: Sri/CI | J31: 45930 | K31: Sprint 7 | N31: covered in sprint 7
A32: 25 | B32: CITA | D32: Category Standardization | E32: Category Standardization | F32: To standardize category chip shown on CITA to refer to category on Product Principal instead of referring on "subfamily" column on produk supplier menu on Control Tower | G32: Nessia | H32: Sri/CI | J32: 45930 | K32: Sprint 7 | N32: covered in sprint 7
A33: 26 | B33: AYO Kasir | D33: Eliminate double transaction happened in AYO due unresponsive Payment gateway | E33: [CDE-25950] AYO Kasir - Limit transaction when FF spam selesaikan pesanan button more than 1x | G33: Marcha | H33: Ida/Adnan | J33: 45930 | K33: Sprint 7 | N33: deployed, 13 aug
A34: 27 | B34: AYO Kasir | D34: Integrate ORF request & process in AYO Kasir | E34: ORF | F34: ORF submission form & process in AYO Kasir to eliminate manual form & manual tracking | G34: Marcha | H34: Ida/Adnan | J34: 45930 | K34: Sprint 7 | N34: covered in sprint 7 ( tp butuh lintas sprint)
A35: 28 | B35: AYO Kasir | D35: Provide inventory data access to AYO Kasir Admin | E35: Stock Count & Stock Adjusment | F35: Laporan inventory harian per toko, per staff, per SKU untuk membantu daily stock take process | G35: Marcha | H35: Ida/Adnan | J35: 45930 | K35: Sprint 7 | N35: covered in sprint 7 ( tp butuh lintas sprint)
A36: 29 | B36: AYO Kasir | D36: Support perpindahan stock antar toko (pemerataan Limited stock & LOGD) | E36: Stock Transfer Store to Store | F36: Stock dapat dipindahkan antar toko (dan antar SLOC) melalui fitur stock movement (beserta history nya) yang dapat di tracking, termasuk dengan penyesuaian di SAP nya | G36: Marcha | H36: Ida/Adnan | J36: 45930 | K36: Sprint 7 | N36: covered in sprint 7 ( tp butuh lintas sprint)
A37: 30 | B37: AYO Kasir | D37: Support loyalty/miles program di IQOS Partne dan allow customization | E37: IP Miles, VAP, Delivery Partner Program | F37: IP memiliki beberapa loyalty toolbox option yang bisa dipilih oleh masing-masing mereka, menyesuaikan dengan kebutuhan bisnis | G37: Marcha | H37: Ida/Adnan | J37: 45930 | K37: Sprint 7 | N37: covered in sprint 7 ( tp butuh lintas sprint)
A38: 31 | B38: AYO Kasir | D38: Provide inventory management & tracking untuk AYO Kasir admin dalam memindahkan stock ke setiap staff | E38: Stock Transfer Admin to Staff | F38: AYO Kasir Admin memerlukan control terhadap inventory management & movement di setiap staff nya, termasuk visibility terkait stock on hand dan movement history yang bisa di track setiap saat untuk monitoring & stock audit | G38: Marcha | H38: Ida/Adnan | J38: 45930 | K38: Sprint 7 | N38: covered in sprint 7
A39: 32 | B39: AYO Kasir | D39: Provide codentify form box for each device purchased --> link device | E39: Device Codentify Input for every device purchased in same order id | F39: Setiap device yang terdapat di dalam suatu transaksi, memerlukan input informasi ke dalam system untuk codentify untuk setiap device. Saat ini, AYO Kasir hanya | G39: Marcha | H39: Ida/Adnan | J39: 45930 | K39: Sprint 7 | N39: covered in sprint 7
A40: 33 | B40: AYO Kasir | D40: Voucher enhancement | E40: Voucher enhancement | F40: Voucher Product Limitation Adjustment | G40: Marcha | H40: Ida/Adnan | J40: 45930 | K40: Sprint 7 | N40: covered in sprint 7
...

Sheet Sprint 8 with Prio (unlocked)
A1: Sprint List | I1: AYO Toko | K1: (3) | L1: DTE | M1: 12
A2: Objective : File ini digunakan oleh CI dan Deployment untuk mentracking List Sprint sepanjang tahun 2025 | I2: MyHero | J2: =66 -> 66 | K2: (1) | L2: AYO Kasir | M2: 97
A3: User yang memiliki akses untuk edit adalah : Tim Deployment & CI | K3: (2) | L3: CITA | M3: 50 | N3: 10 | O3: allocate to AYO Kasir
A4: Sprint 7, need tobe check by tim CI | L4: AYO Mitra
L5: AMO | M5: 107 | P5: SPRINT 8
C6: CI Team | G6: CI Team | M6: assume 1 sprint = 10 mandays | P6: 45904 | Q6: 45920 | R6: 45927 | S6: 45929 | T6: 45958
A7: No | B7: Platform (Aplikasi) | C7: Dependency | D7: Background | E7: Objective | F7: Description | G7: Product Manager | H7: ITPD | I7: Requestor | J7: Chanel | K7: Expected Deployed | L7: Sprint | M7: Rank Prio | N7: Sprint Carry Over | O7: Update from 1st backlog | P7: Update 1 | Q7: Update 2 | R7: Update 3 | S7: Update 4 | T7: Update 5 | U7: Update 6 | V7: Update 7 | W7: PRD | X7: JIRA | Y7: Mandays
A8: 1 | B8: AMO | D8: QR code phase 2 (adding button to top up canvassing during pengiriman CITA di AMO offline) | E8: QR code phase 2 (adding button to top up canvassing during pengiriman CITA di AMO offline) | F8: QR code phase 2 (adding button to top up canvassing during pengiriman CITA di AMO offline) | G8: Marcha | I8: Duta | K8: 45870 | L8: Sprint 6 | P8: Done
A9: 2 | B9: AMO | D9: Canvassing = Product assortment / carousel untuk focused product | E9: Canvassing = Product assortment / carousel untuk focused product | F9: Canvassing = Product assortment / carousel untuk focused product follow B2B | G9: Marcha | I9: Duta | K9: 45870 | L9: Sprint 6 | P9: Done
A10: 3 | B10: AMO | D10: SKU reminder untuk focused product sebelum dilakukan payment | E10: SKU reminder untuk focused product sebelum dilakukan payment | F10: SKU reminder untuk focused product sebelum dilakukan payment (Re-offering) | G10: Marcha | I10: Duta | K10: 45870 | L10: Sprint 6 | P10: Done
A11: 4 | B11: AMO | D11: Mendapatkan progress achievement PG (Unique Call, Volume canvass & CITA) dari PBI Reporting AMO | E11: Mendapatkan progress achievement PG (Unique Call, Volume canvass & CITA) dari PBI Reporting AMO | F11: Mendapatkan progress achievement PG (Unique Call, Volume canvass & CITA) dari PBI Reporting AMO | G11: Marcha | I11: Duta | K11: 45870 | L11: Sprint 6 | P11: Done
A12: 5 | B12: AMO | D12: Add tab "Laporan" untuk menunjukan progress achievement PG (Unique Call, Volume canvass & CITA) | E12: Add tab "Laporan" untuk menunjukan progress achievement PG (Unique Call, Volume canvass & CITA) | F12: Add tab "Laporan" untuk menunjukan progress achievement PG (Unique Call, Volume canvass & CITA) | G12: Marcha | I12: Duta | K12: 45870 | L12: Sprint 6 | P12: Done
A13: 6 | B13: AMO | D13: Canvassing | E13: Fitur Scan QR pada mode Canvassing | F13: Edit text Kunjungan Non Downline menjadi "Mulai Kunjungan", direct page to fitur Scan QR dan akan ter-mapping ke customer registered HMS as map to RE | G13: Marcha | I13: Duta | K13: 45930 | L13: Sprint 7 | O13: covered in sprint 7
A14: 7 | B14: AMO Existing & AMO Plus | D14: The logic can cause processing inefficiency and high server load in a long run | E14: More effective process (if still needed) | F14: Change the logic from actively query-ing the data from data order table and whitelisting table in database upon completion of delivery order to using flagging on file download. | G14: Jimmy H./ M. Yusron | L14: Sprint 8 | M14: 7
A15: 8 | B15: AMO Existing & Plus | D15: Needed to help prepare the product D-1 prior to delivery | E15: To effectively categorized packaged product by the PG name | F15: Invoice pada transaksi selain memunculkan nama PG, juga no HP PG | G15: Jimmy H./ M. Yusron | L15: Sprint 8 | M15: 10
A16: 9 | B16: AMO plus | D16: Filter type outlet di maps | E16: Filter type outlet di maps | F16: Selecting toko yang tampil di peta pada AMO | G16: Maulana | I16: Duta | K16: 45930 | L16: Sprint 7
A17: 10 | B17: AMO Plus | D17: Search downline PG | E17: Search downline PG | F17: Fitur search downline salesman/mitra di AMO+ (seperti di AMO Existing) | G17: Maulana | I17: Duta | K17: 45930 | L17: Sprint 7 | O17: covered in sprint 7
A18: 11 | B18: AMO Plus | D18: Remaining stock product PG | E18: Remaining stock product PG | F18: Info sisa stok yang dibawa PG di page transaksi | G18: Maulana | I18: Duta | K18: 45930 | L18: Sprint 7 | O18: covered in sprint 7
A19: 12 | B19: AMO Plus | D19: Price product di page transaksi | E19: Price product di page transaksi | F19: Info price product / SKU di halaman transaksi | G19: Maulana | I19: Duta | K19: 45930 | L19: Sprint 7 | O19: covered in sprint 7
A20: 13 | B20: AMO Plus | D20: Reconciliation report | E20: Reconciliation report | F20: Menggabungkan LPU dan BPPB pada AMO | G20: Maulana | I20: Duta | K20: 45930 | L20: Sprint 7 | O20: covered in sprint 7
A21: 14 | B21: AMO Plus | D21: AYO Mitra Plus Hybrid Mode | E21: AYO Mitra Plus Hybrid Mode | F21: AMO Existing bisa digunakan dengan AYO Mitra yang baru | I21: Sri P | K21: 45955 | L21: Sprint 8 (prio2) | M21: 1
A22: 15 | B22: AMO Plus | D22: Sometimes PG completing delivery more than 6 p.m. when admin has gone home so they cannot help PG to carry over incomplete order to next day | E22: To avoid incomplete order to auto-cancelled when admin has finished their shift | F22: Carry over pengiriman CITA yang belum bisa diantarkan ke besok hari dari AMO PG | G22: Jimmy H./ M. Yusron | L22: Sprint 8 | M22: 4
A23: 16 | B23: AMO Plus | D23: To avoid calculation error when the visit is retrieved via PBI (or any other reporting mechanism) | E23: To avoid calculation error when the visit is retrieved via PBI (or any other reporting mechanism) | F23: Update visit status when Selesaikan Pesanan (currently in DWH visit status is 0, even the delivery has been completed) | G23: Jimmy H./ M. Yusron | L23: Sprint 8 | M23: 11
A24: 17 | B24: AMO Plus | D24: Adanya kemungkinan duplikasi atau double counting pada Data PG Performance Tracker | E24: Fixing the calculation of Data PG Performance Tracker | F24: Calculation PG Performance Tracker yang dikirimkan melalui reverse ETL diharapkan bisa disummary tiap periode performance sehingga perlu enhancement juga dari sisi AMO | G24: Jimmy H./ M. Yusron | I24: Jimmy H. | L24: Sprint 8 | M24: 9
A25: 18 | B25: AMO Plus | D25: To monitor PG activity and calculate a more accurate SLA | E25: To monitor PG activity and calculate a more accurate SLA | F25: Upon completion of CITA Delivery Order it is required to record the Longitude and Latitude | G25: Jimmy H./ M. Yusron | L25: Sprint 8 | M25: 6
A26: 19 | B26: AMO Plus & AYO Mitra Plus | D26: Heavy queries in AMO: When AMO (AYO Mitra Order / AMO Plus for Pasgar Sinergi) opens BPPB and/or processes CITA orders, the app runs heavy queries to recompute initial stock recommendation and then another query to check stock. This is inefficient and prone to service spikes at higher concurrency. Stok/BPPB checks should only reference the post-“Proses” snapshot table (initial load result), not re-calculate on each screen/process. | E26: Improve Query BPPB & Stock Checking when processing CITA Order | F26: - Eliminate heavy queries in AMO for BPPB and CITA processing - Guarantee stock deduction for all CITA orders that enter BPPB even if the SKU is not listed by the Mitra - Align BPPB across AYO Mitra & AMO (single source of truth). - AMO Plus operates smoothly for ≥5,000 Pasgar concurrently, with ≥35 CITA store orders per Pasgar per day | G26: Varhan/Jun/Jimmy | I26: Varhan | K26: 45930 | L26: Sprint 7 | M26: 13 | Q26: Sprint 7 --> ongoing development | X26: https://jira.app.pconnect.biz/browse/CDE-26740
A27: 20 | B27: AYO Kasir | D27: Eliminate double transaction happened in AYO due unresponsive Payment gateway | E27: [CDE-25950] AYO Kasir - Limit transaction when FF spam selesaikan pesanan button more than 1x | G27: Marcha | I27: Ida/Adnan | K27: 45930 | L27: Sprint 7 | O27: deployed, 13 aug
A28: 21 | B28: AYO Kasir | D28: Integrate ORF request & process in AYO Kasir | E28: ORF | F28: ORF submission form & process in AYO Kasir to eliminate manual form & manual tracking | G28: Marcha | I28: Ida/Adnan | K28: 45930 | L28: Sprint 7 | O28: covered in sprint 7 ( tp butuh lintas sprint)
A29: 22 | B29: AYO Kasir | D29: Provide inventory data access to AYO Kasir Admin | E29: Stock Count & Stock Adjusment | F29: Laporan inventory harian per toko, per staff, per SKU untuk membantu daily stock take process | G29: Marcha | I29: Ida/Adnan | K29: 45930 | L29: Sprint 7 | O29: covered in sprint 7 ( tp butuh lintas sprint)
A30: 23 | B30: AYO Kasir | D30: Support perpindahan stock antar toko (pemerataan Limited stock & LOGD) | E30: Stock Transfer Store to Store | F30: Stock dapat dipindahkan antar toko (dan antar SLOC) melalui fitur stock movement (beserta history nya) yang dapat di tracking, termasuk dengan penyesuaian di SAP nya | G30: Marcha | I30: Ida/Adnan | K30: 45930 | L30: Sprint 7 | O30: covered in sprint 7 ( tp butuh lintas sprint)
A31: 24 | B31: AYO Kasir | D31: Support loyalty/miles program di IQOS Partne dan allow customization | E31: IP Miles, VAP, Delivery Partner Program | F31: IP memiliki beberapa loyalty toolbox option yang bisa dipilih oleh masing-masing mereka, menyesuaikan dengan kebutuhan bisnis | G31: Marcha | I31: Ida/Adnan | K31: 45930 | L31: Sprint 7 | O31: covered in sprint 7 ( tp butuh lintas sprint)
A32: 25 | B32: AYO Kasir | D32: Provide inventory management & tracking untuk AYO Kasir admin dalam memindahkan stock ke setiap staff | E32: Stock Transfer Admin to Staff | F32: AYO Kasir Admin memerlukan control terhadap inventory management & movement di setiap staff nya, termasuk visibility terkait stock on hand dan movement history yang bisa di track setiap saat untuk monitoring & stock audit | G32: Marcha | I32: Ida/Adnan | K32: 45930 | L32: Sprint 7 | O32: covered in sprint 7
A33: 26 | B33: AYO Kasir | D33: Provide codentify form box for each device purchased --> link device | E33: Device Codentify Input for every device purchased in same order id | F33: Setiap device yang terdapat di dalam suatu transaksi, memerlukan input informasi ke dalam system untuk codentify untuk setiap device. Saat ini, AYO Kasir hanya | G33: Marcha | I33: Ida/Adnan | K33: 45930 | L33: Sprint 7 | O33: covered in sprint 7
A34: 27 | B34: AYO Kasir | D34: Voucher enhancement | E34: Voucher enhancement | F34: Voucher Product Limitation Adjustment | G34: Marcha | I34: Ida/Adnan | K34: 45930 | L34: Sprint 7 | O34: covered in sprint 7
A35: 28 | B35: AYO Kasir | D35: Improve product demo experience for better trial & acceptance | E35: Taste Advisory | F35: Taste Advisory feature yang saat ini tersedia di Qoncierge untuk bisa di integrate ke AYO Kasir untuk seamless journey & data connection (konsumen & transaksi) | G35: Marcha | I35: Ida/Adnan | K35: 45930 | L35: Sprint 7 | O35: covered in sprint 7
A36: 29 | B36: AYO Kasir | D36: Enable AYO Kasir Web Version to be fully operated in IOS based device (All Pages) | E36: AYO Kasir responsive (phase 2) - Compatibility in mobile version (web) | F36: Enable AYO Kasir web to be accessed in mobile browser | I36: Ida/Adnan | K36: 45955 | L36: Sprint 8 (prio1)
A37: 30 | B37: AYO Kasir | D37: Enable AYO Kasir Web Version to be fully operated in IOS based device (Catalog Pages) | E37: AYO Kasir responsive (phase 3) - Compatibility in mobile version (catalog) | F37: Enable AYO Kasir web to be accessed in mobile browser | I37: Ida/Adnan | K37: 45955 | L37: Sprint 8 (prio1)
A38: 31 | B38: AYO Kasir | D38: Data Security - Global Requirement | E38: Pentest Finding: Show generic error message to omit info if phone number exists in database | F38: As a part of security finding, we need to create 1 login page for user to insert phone number and passcode, and show a generic error message to users. The deadline to fix the finding is in October 2025. | I38: Ida/CI | K38: 45955 | L38: Sprint 8 (prio1)
A39: 32 | B39: AYO Kasir | D39: Improve ORF accuracy by each touchpoint to ensure sufficient inventory management & security | E39: AYO Kasir - ORF Warehouse Replenishment - Jira (Phase 3) - PKM ORF | F39: AYO Kasir to be automatically provide ORF Qty recommendation for each touchpoints/coach based on Sales historical & current stock | I39: Ida/Adnan | K39: 45955 | L39: Sprint 8 (prio1)
A40: 33 | B40: AYO Kasir | D40: Provide proper replacement service with proper process in terms of inventory & finance management, similar to DCE configuration | E40: phase 1: input replacement transaction phase 2: QURE in AYO Kasir | F40: Feature to enable SFP device replacement in AYO Kasir by inputting replacement transaction and having DCE API to check device eligibility & record the replacement. | I40: Ida/Adnan | K40: 45955 | L40: Sprint 8 (prio1)
...

Sheet Kasir Qoncierge
A1: Sprint List | H1: AYO Toko | J1: -3 | K1: DTE | L1: 12
A2: Objective : File ini digunakan oleh CI dan Deployment untuk mentracking List Sprint sepanjang tahun 2025 | H2: MyHero | I2: 66 | J2: -1 | K2: AYO Kasir | L2: 97
A3: User yang memiliki akses untuk edit adalah : Tim Deployment & CI | J3: -2 | K3: CITA | L3: 50 | M3: 10 | N3: allocate to AYO Kasir
A4: Sprint 7, need tobe check by tim CI | K4: AYO Mitra
K5: AMO | L5: 107 | O5: SPRINT 8
C6: CI Team | G6: CI Team | L6: assume 1 sprint = 10 mandays | O6: 45904 | P6: 45916 | Q6: 45919 | R6: 45926 | S6: 45958
A7: No | B7: Platform (Aplikasi) | C7: Dependency | D7: Background | E7: Objective | F7: Description | G7: Product Manager | H7: Requestor | I7: Chanel | J7: Expected Deployed | K7: Sprint | L7: Rank Prio | M7: Sprint Carry Over | N7: Update 0 8/28 | O7: Update 1 | P7: Update 2 | Q7: Update 3 | R7: Update 4 | S7: Update 5 | T7: Update 6 | U7: Update 7 | V7: JIRA | W7: Mandays
A8: 1 | B8: AMO | D8: QR code phase 2 (adding button to top up canvassing during pengiriman CITA di AMO offline) | E8: QR code phase 2 (adding button to top up canvassing during pengiriman CITA di AMO offline) | F8: QR code phase 2 (adding button to top up canvassing during pengiriman CITA di AMO offline) | G8: Marcha | H8: Duta | J8: 45894 | K8: Sprint 6 | O8: Done
A9: 2 | B9: AMO | D9: Canvassing = Product assortment / carousel untuk focused product | E9: Canvassing = Product assortment / carousel untuk focused product | F9: Canvassing = Product assortment / carousel untuk focused product follow B2B | G9: Marcha | H9: Duta | J9: 45894 | K9: Sprint 6 | O9: Done
A10: 3 | B10: AMO | D10: SKU reminder untuk focused product sebelum dilakukan payment | E10: SKU reminder untuk focused product sebelum dilakukan payment | F10: SKU reminder untuk focused product sebelum dilakukan payment (Re-offering) | G10: Marcha | H10: Duta | J10: 45894 | K10: Sprint 6 | O10: Done
A11: 4 | B11: AMO | D11: Mendapatkan progress achievement PG (Unique Call, Volume canvass & CITA) dari PBI Reporting AMO | E11: Mendapatkan progress achievement PG (Unique Call, Volume canvass & CITA) dari PBI Reporting AMO | F11: Mendapatkan progress achievement PG (Unique Call, Volume canvass & CITA) dari PBI Reporting AMO | G11: Marcha | H11: Duta | J11: 45894 | K11: Sprint 6 | O11: Done
A12: 5 | B12: AMO | D12: Add tab "Laporan" untuk menunjukan progress achievement PG (Unique Call, Volume canvass & CITA) | E12: Add tab "Laporan" untuk menunjukan progress achievement PG (Unique Call, Volume canvass & CITA) | F12: Add tab "Laporan" untuk menunjukan progress achievement PG (Unique Call, Volume canvass & CITA) | G12: Marcha | H12: Duta | J12: 45894 | K12: Sprint 6 | O12: Done
A13: 6 | B13: AYO Principal | D13: Elevate Automation | E13: Elevate - Data Entry | F13: Capability untuk user bisa melakukan WO atau guideline submission | G13: Nessia | H13: Nika | J13: 45925 | K13: Sprint 7
A14: 7 | B14: AYO Principal | D14: Elevate Automation | E14: Elevate - Email generator | F14: Capability elevate untuk generate email ke zone sehubungan dengan WO/guideline yang diinputkan di Elevate | G14: Nessia | H14: Nika | J14: 45925 | K14: Sprint 7
A15: 8 | B15: AYO Principal | D15: Elevate Automation | E15: Elevate - Cycle calendar | F15: Capability untuk show dan filter WO atau guideline yang impact ke waktu week tertentu | G15: Nessia | H15: Nika | J15: 45925 | K15: Sprint 7
A16: 9 | B16: Control Tower | D16: Seamless data upload | E16: CT Update Schedulling and rework data entry template | F16: Flexybility update data in CT by add feature schedule | G16: Nessia | H16: Sri P | J16: 45925 | K16: Sprint 7 | M16: Sprint 8 | N16: carry over to the next sprint
A17: 10 | B17: AMO | D17: Canvassing | E17: Fitur Scan QR pada mode Canvassing | F17: Edit text Kunjungan Non Downline menjadi "Mulai Kunjungan", direct page to fitur Scan QR dan akan ter-mapping ke customer registered HMS as map to RE | G17: Marcha | H17: Duta | J17: 45925 | K17: Sprint 7 | N17: covered in sprint 7
A18: 11 | B18: AMO plus | D18: Filter type outlet di maps | E18: Filter type outlet di maps | F18: Selecting toko yang tampil di peta pada AMO | G18: Maulana | H18: Duta | J18: 45925 | K18: Sprint 7
A19: 12 | B19: AMO Plus | D19: Search downline PG | E19: Search downline PG | F19: Fitur search downline salesman/mitra di AMO+ (seperti di AMO Existing) | G19: Maulana | H19: Duta | J19: 45925 | K19: Sprint 7 | N19: covered in sprint 7
A20: 13 | B20: AMO Plus | D20: Remaining stock product PG | E20: Remaining stock product PG | F20: Info sisa stok yang dibawa PG di page transaksi | G20: Maulana | H20: Duta | J20: 45925 | K20: Sprint 7 | N20: covered in sprint 7
A21: 14 | B21: AMO Plus | D21: Price product di page transaksi | E21: Price product di page transaksi | F21: Info price product / SKU di halaman transaksi | G21: Maulana | H21: Duta | J21: 45925 | K21: Sprint 7 | N21: covered in sprint 7
A22: 15 | B22: AMO Plus | D22: Reconciliation report | E22: Reconciliation report | F22: Menggabungkan LPU dan BPPB pada AMO | G22: Maulana | H22: Duta | J22: 45925 | K22: Sprint 7 | N22: covered in sprint 7
A23: 16 | B23: AYO Mitra Plus | D23: Manual assign by PG khususnya jika ada PG yg tidak masuk | E23: Manual assign by PG khususnya jika ada PG yg tidak masuk | F23: Manual assign by PG khususnya jika ada PG yg tidak masuk | G23: Maulana | H23: Sri P | J23: 45925 | K23: Sprint 7 | N23: covered in sprint 7
A24: 17 | B24: AYO Mitra Plus | D24: Grouping order by PG di hari H-1 | E24: Grouping order by PG di hari H-1 | F24: Grouping order by PG di hari H | G24: Maulana | H24: Sri P | J24: 45925 | K24: Sprint 7 | N24: covered in sprint 7
A25: 18 | B25: AYO Mitra Plus | D25: Mitra tetap dapat melakukan cluster, meskipun masih ada pesanan dalam pengiriman | E25: Mitra tetap dapat melakukan cluster, meskipun masih ada pesanan dalam pengiriman | F25: Mitra tetap dapat melakukan proses pesanan, ketika ada pesanan baru | G25: Maulana | H25: Sri P | J25: 45925 | K25: Sprint 7 | N25: covered in sprint 7
A26: 19 | B26: AYO Mitra Plus | D26: Fixing miss cluster | E26: Fixing miss cluster | F26: Fixing miss cluster | G26: Maulana | H26: Sri P | J26: 45925 | K26: Sprint 7 | N26: covered in sprint 7
A27: 20 | B27: AYO Mitra Plus | D27: Simply Initial load reccomendation | E27: Simply Initial load reccomendation | F27: Simply Initial load reccomendation | G27: Maulana | H27: Sri P | J27: 45925 | K27: Sprint 7 | N27: covered in sprint 7
A28: 21 | B28: MyHero | D28: Hygiene document | E28: LPU | F28: Saat ini yang muncul ketika cetak LPU hanyalah tanggal cetak, bukan tanggal journeynya | G28: Hadi Pram | H28: Nika | J28: 45925 | K28: Sprint 7
F29: Add 1 field for tanggal journey
A30: 22 | B30: MyHero | D30: Multicategory document | E30: BPPB, Add load | F30: On top of kode barang, penambahan Prod name (masking) di BPPB untuk FMCG | G30: Hadi Pram | H30: Nika | J30: 45925 | K30: Sprint 7
A31: 23 | B31: MyHero | D31: Multicategory document | E31: BPPB, Add load | F31: Printed doc DN after jourgen dan input initial load by back end | G31: Hadi Pram | H31: Nika | J31: 45925 | K31: Sprint 7
A32: 24 | B32: CITA | D32: Detect distinct SKU and pack quantity inside paket produk | E32: Detect distinct SKU and pack quantity inside paket produk | F32: To be able to detect quantity of packs inside Paket Produk | G32: Nessia | H32: Sri/CI | J32: 45925 | K32: Sprint 7 | N32: covered in sprint 7
A33: 25 | B33: CITA | D33: Category Standardization | E33: Category Standardization | F33: To standardize category chip shown on CITA to refer to category on Product Principal instead of referring on "subfamily" column on produk supplier menu on Control Tower | G33: Nessia | H33: Sri/CI | J33: 45925 | K33: Sprint 7 | N33: covered in sprint 7
A34: 26 | B34: AYO Kasir | D34: Eliminate double transaction happened in AYO due unresponsive Payment gateway | E34: [CDE-25950] AYO Kasir - Limit transaction when FF spam selesaikan pesanan button more than 1x | G34: Marcha | H34: Ida/Adnan | J34: 45925 | K34: Sprint 7 | N34: deployed, 13 aug
A35: 27 | B35: AYO Kasir | D35: Integrate ORF request & process in AYO Kasir | E35: ORF | F35: ORF submission form & process in AYO Kasir to eliminate manual form & manual tracking | G35: Marcha | H35: Ida/Adnan | J35: 45925 | K35: Sprint 7 | N35: covered in sprint 7 ( tp butuh lintas sprint)
A36: 28 | B36: AYO Kasir | D36: Provide inventory data access to AYO Kasir Admin | E36: Stock Count & Stock Adjusment | F36: Laporan inventory harian per toko, per staff, per SKU untuk membantu daily stock take process | G36: Marcha | H36: Ida/Adnan | J36: 45925 | K36: Sprint 7 | N36: covered in sprint 7 ( tp butuh lintas sprint)
A37: 29 | B37: AYO Kasir | D37: Support perpindahan stock antar toko (pemerataan Limited stock & LOGD) | E37: Stock Transfer Store to Store | F37: Stock dapat dipindahkan antar toko (dan antar SLOC) melalui fitur stock movement (beserta history nya) yang dapat di tracking, termasuk dengan penyesuaian di SAP nya | G37: Marcha | H37: Ida/Adnan | J37: 45925 | K37: Sprint 7 | N37: covered in sprint 7 ( tp butuh lintas sprint)
A38: 30 | B38: AYO Kasir | D38: Support loyalty/miles program di IQOS Partne dan allow customization | E38: IP Miles, VAP, Delivery Partner Program | F38: IP memiliki beberapa loyalty toolbox option yang bisa dipilih oleh masing-masing mereka, menyesuaikan dengan kebutuhan bisnis | G38: Marcha | H38: Ida/Adnan | J38: 45925 | K38: Sprint 7 | N38: covered in sprint 7 ( tp butuh lintas sprint)
A39: 31 | B39: AYO Kasir | D39: Provide inventory management & tracking untuk AYO Kasir admin dalam memindahkan stock ke setiap staff | E39: Stock Transfer Admin to Staff | F39: AYO Kasir Admin memerlukan control terhadap inventory management & movement di setiap staff nya, termasuk visibility terkait stock on hand dan movement history yang bisa di track setiap saat untuk monitoring & stock audit | G39: Marcha | H39: Ida/Adnan | J39: 45925 | K39: Sprint 7 | N39: covered in sprint 7
A40: 32 | B40: AYO Kasir | D40: Provide codentify form box for each device purchased --> link device | E40: Device Codentify Input for every device purchased in same order id | F40: Setiap device yang terdapat di dalam suatu transaksi, memerlukan input informasi ke dalam system untuk codentify untuk setiap device. Saat ini, AYO Kasir hanya | G40: Marcha | H40: Ida/Adnan | J40: 45925 | K40: Sprint 7 | N40: covered in sprint 7
...

Sheet Sprint 8 with Prio (unlocked) 2
A1: Sprint List | H1: AYO Toko | J1: (3) | K1: DTE | L1: 12
A2: Objective : File ini digunakan oleh CI dan Deployment untuk mentracking List Sprint sepanjang tahun 2025 | H2: MyHero | I2: =66 -> 66 | J2: (1) | K2: AYO Kasir | L2: 97
A3: User yang memiliki akses untuk edit adalah : Tim Deployment & CI | J3: (2) | K3: CITA | L3: 50 | M3: 10 | N3: allocate to AYO Kasir
A4: Sprint 7, need tobe check by tim CI | K4: AYO Mitra
K5: AMO | L5: 107 | O5: SPRINT 8
C6: CI Team | G6: CI Team | L6: assume 1 sprint = 10 mandays | O6: 45904 | P6: 45920 | Q6: 45927 | R6: 45929 | S6: 45958
A7: No | B7: Platform (Aplikasi) | C7: Dependency | D7: Background | E7: Objective | F7: Description | G7: Product Manager | H7: Requestor | I7: Chanel | J7: Expected Deployed | K7: Sprint | L7: Rank Prio | M7: Sprint Carry Over | N7: Update 0 8/28 | O7: Update 1 | P7: Update 2 | Q7: Update 3 | R7: Update 4 | S7: Update 5 | T7: Update 6 | U7: Update 7 | V7: JIRA | W7: Mandays
A8: 1 | B8: AMO | D8: QR code phase 2 (adding button to top up canvassing during pengiriman CITA di AMO offline) | E8: QR code phase 2 (adding button to top up canvassing during pengiriman CITA di AMO offline) | F8: QR code phase 2 (adding button to top up canvassing during pengiriman CITA di AMO offline) | G8: Marcha | H8: Duta | J8: 45870 | K8: Sprint 6 | O8: Done
A9: 2 | B9: AMO | D9: Canvassing = Product assortment / carousel untuk focused product | E9: Canvassing = Product assortment / carousel untuk focused product | F9: Canvassing = Product assortment / carousel untuk focused product follow B2B | G9: Marcha | H9: Duta | J9: 45870 | K9: Sprint 6 | O9: Done
A10: 3 | B10: AMO | D10: SKU reminder untuk focused product sebelum dilakukan payment | E10: SKU reminder untuk focused product sebelum dilakukan payment | F10: SKU reminder untuk focused product sebelum dilakukan payment (Re-offering) | G10: Marcha | H10: Duta | J10: 45870 | K10: Sprint 6 | O10: Done
A11: 4 | B11: AMO | D11: Mendapatkan progress achievement PG (Unique Call, Volume canvass & CITA) dari PBI Reporting AMO | E11: Mendapatkan progress achievement PG (Unique Call, Volume canvass & CITA) dari PBI Reporting AMO | F11: Mendapatkan progress achievement PG (Unique Call, Volume canvass & CITA) dari PBI Reporting AMO | G11: Marcha | H11: Duta | J11: 45870 | K11: Sprint 6 | O11: Done
A12: 5 | B12: AMO | D12: Add tab "Laporan" untuk menunjukan progress achievement PG (Unique Call, Volume canvass & CITA) | E12: Add tab "Laporan" untuk menunjukan progress achievement PG (Unique Call, Volume canvass & CITA) | F12: Add tab "Laporan" untuk menunjukan progress achievement PG (Unique Call, Volume canvass & CITA) | G12: Marcha | H12: Duta | J12: 45870 | K12: Sprint 6 | O12: Done
A13: 6 | B13: AYO Principal | D13: Elevate Automation | E13: Elevate - Data Entry | F13: Capability untuk user bisa melakukan WO atau guideline submission | G13: Nessia | H13: Nika | J13: 45930 | K13: Sprint 7
A14: 7 | B14: AYO Principal | D14: Elevate Automation | E14: Elevate - Email generator | F14: Capability elevate untuk generate email ke zone sehubungan dengan WO/guideline yang diinputkan di Elevate | G14: Nessia | H14: Nika | J14: 45930 | K14: Sprint 7
A15: 8 | B15: AYO Principal | D15: Elevate Automation | E15: Elevate - Cycle calendar | F15: Capability untuk show dan filter WO atau guideline yang impact ke waktu week tertentu | G15: Nessia | H15: Nika | J15: 45930 | K15: Sprint 7
A16: 9 | B16: Control Tower | D16: Seamless data upload | E16: CT Update Schedulling and rework data entry template | F16: Flexybility update data in CT by add feature schedule | G16: Nessia | H16: Sri P | J16: 45930 | K16: Sprint 7 | M16: Sprint 8 | N16: carry over to the next sprint
A17: 10 | B17: AMO | D17: Canvassing | E17: Fitur Scan QR pada mode Canvassing | F17: Edit text Kunjungan Non Downline menjadi "Mulai Kunjungan", direct page to fitur Scan QR dan akan ter-mapping ke customer registered HMS as map to RE | G17: Marcha | H17: Duta | J17: 45930 | K17: Sprint 7 | N17: covered in sprint 7
A18: 11 | B18: AMO plus | D18: Filter type outlet di maps | E18: Filter type outlet di maps | F18: Selecting toko yang tampil di peta pada AMO | G18: Maulana | H18: Duta | J18: 45930 | K18: Sprint 7
A19: 12 | B19: AMO Plus | D19: Search downline PG | E19: Search downline PG | F19: Fitur search downline salesman/mitra di AMO+ (seperti di AMO Existing) | G19: Maulana | H19: Duta | J19: 45930 | K19: Sprint 7 | N19: covered in sprint 7
A20: 13 | B20: AMO Plus | D20: Remaining stock product PG | E20: Remaining stock product PG | F20: Info sisa stok yang dibawa PG di page transaksi | G20: Maulana | H20: Duta | J20: 45930 | K20: Sprint 7 | N20: covered in sprint 7
A21: 14 | B21: AMO Plus | D21: Price product di page transaksi | E21: Price product di page transaksi | F21: Info price product / SKU di halaman transaksi | G21: Maulana | H21: Duta | J21: 45930 | K21: Sprint 7 | N21: covered in sprint 7
A22: 15 | B22: AMO Plus | D22: Reconciliation report | E22: Reconciliation report | F22: Menggabungkan LPU dan BPPB pada AMO | G22: Maulana | H22: Duta | J22: 45930 | K22: Sprint 7 | N22: covered in sprint 7
A23: 16 | B23: AYO Mitra Plus | D23: Manual assign by PG khususnya jika ada PG yg tidak masuk | E23: Manual assign by PG khususnya jika ada PG yg tidak masuk | F23: Manual assign by PG khususnya jika ada PG yg tidak masuk | G23: Maulana | H23: Sri P | J23: 45930 | K23: Sprint 7 | N23: covered in sprint 7
A24: 17 | B24: AYO Mitra Plus | D24: Grouping order by PG di hari H-1 | E24: Grouping order by PG di hari H-1 | F24: Grouping order by PG di hari H | G24: Maulana | H24: Sri P | J24: 45930 | K24: Sprint 7 | N24: covered in sprint 7
A25: 18 | B25: AYO Mitra Plus | D25: Mitra tetap dapat melakukan cluster, meskipun masih ada pesanan dalam pengiriman | E25: Mitra tetap dapat melakukan cluster, meskipun masih ada pesanan dalam pengiriman | F25: Mitra tetap dapat melakukan proses pesanan, ketika ada pesanan baru | G25: Maulana | H25: Sri P | J25: 45930 | K25: Sprint 7 | N25: covered in sprint 7
A26: 19 | B26: AYO Mitra Plus | D26: Fixing miss cluster | E26: Fixing miss cluster | F26: Fixing miss cluster | G26: Maulana | H26: Sri P | J26: 45930 | K26: Sprint 7 | N26: covered in sprint 7
A27: 20 | B27: AYO Mitra Plus | D27: Simply Initial load reccomendation | E27: Simply Initial load reccomendation | F27: Simply Initial load reccomendation | G27: Maulana | H27: Sri P | J27: 45930 | K27: Sprint 7 | N27: covered in sprint 7
A28: 21 | B28: MyHero | D28: Hygiene document | E28: LPU | F28: Saat ini yang muncul ketika cetak LPU hanyalah tanggal cetak, bukan tanggal journeynya Add 1 field for tanggal journey | G28: Hadi Pram | H28: Nika | J28: 45930 | K28: Sprint 7
A29: 22 | B29: MyHero | D29: Multicategory document | E29: BPPB, Add load | F29: On top of kode barang, penambahan Prod name (masking) di BPPB untuk FMCG | G29: Hadi Pram | H29: Nika | J29: 45930 | K29: Sprint 7
A30: 23 | B30: MyHero | D30: Multicategory document | E30: BPPB, Add load | F30: Printed doc DN after jourgen dan input initial load by back end | G30: Hadi Pram | H30: Nika | J30: 45930 | K30: Sprint 7
A31: 24 | B31: CITA | D31: Detect distinct SKU and pack quantity inside paket produk | E31: Detect distinct SKU and pack quantity inside paket produk | F31: To be able to detect quantity of packs inside Paket Produk | G31: Nessia | H31: Sri/CI | J31: 45930 | K31: Sprint 7 | N31: covered in sprint 7
A32: 25 | B32: CITA | D32: Category Standardization | E32: Category Standardization | F32: To standardize category chip shown on CITA to refer to category on Product Principal instead of referring on "subfamily" column on produk supplier menu on Control Tower | G32: Nessia | H32: Sri/CI | J32: 45930 | K32: Sprint 7 | N32: covered in sprint 7
A33: 26 | B33: AYO Kasir | D33: Eliminate double transaction happened in AYO due unresponsive Payment gateway | E33: [CDE-25950] AYO Kasir - Limit transaction when FF spam selesaikan pesanan button more than 1x | G33: Marcha | H33: Ida/Adnan | J33: 45930 | K33: Sprint 7 | N33: deployed, 13 aug
A34: 27 | B34: AYO Kasir | D34: Integrate ORF request & process in AYO Kasir | E34: ORF | F34: ORF submission form & process in AYO Kasir to eliminate manual form & manual tracking | G34: Marcha | H34: Ida/Adnan | J34: 45930 | K34: Sprint 7 | N34: covered in sprint 7 ( tp butuh lintas sprint)
A35: 28 | B35: AYO Kasir | D35: Provide inventory data access to AYO Kasir Admin | E35: Stock Count & Stock Adjusment | F35: Laporan inventory harian per toko, per staff, per SKU untuk membantu daily stock take process | G35: Marcha | H35: Ida/Adnan | J35: 45930 | K35: Sprint 7 | N35: covered in sprint 7 ( tp butuh lintas sprint)
A36: 29 | B36: AYO Kasir | D36: Support perpindahan stock antar toko (pemerataan Limited stock & LOGD) | E36: Stock Transfer Store to Store | F36: Stock dapat dipindahkan antar toko (dan antar SLOC) melalui fitur stock movement (beserta history nya) yang dapat di tracking, termasuk dengan penyesuaian di SAP nya | G36: Marcha | H36: Ida/Adnan | J36: 45930 | K36: Sprint 7 | N36: covered in sprint 7 ( tp butuh lintas sprint)
A37: 30 | B37: AYO Kasir | D37: Support loyalty/miles program di IQOS Partne dan allow customization | E37: IP Miles, VAP, Delivery Partner Program | F37: IP memiliki beberapa loyalty toolbox option yang bisa dipilih oleh masing-masing mereka, menyesuaikan dengan kebutuhan bisnis | G37: Marcha | H37: Ida/Adnan | J37: 45930 | K37: Sprint 7 | N37: covered in sprint 7 ( tp butuh lintas sprint)
A38: 31 | B38: AYO Kasir | D38: Provide inventory management & tracking untuk AYO Kasir admin dalam memindahkan stock ke setiap staff | E38: Stock Transfer Admin to Staff | F38: AYO Kasir Admin memerlukan control terhadap inventory management & movement di setiap staff nya, termasuk visibility terkait stock on hand dan movement history yang bisa di track setiap saat untuk monitoring & stock audit | G38: Marcha | H38: Ida/Adnan | J38: 45930 | K38: Sprint 7 | N38: covered in sprint 7
A39: 32 | B39: AYO Kasir | D39: Provide codentify form box for each device purchased --> link device | E39: Device Codentify Input for every device purchased in same order id | F39: Setiap device yang terdapat di dalam suatu transaksi, memerlukan input informasi ke dalam system untuk codentify untuk setiap device. Saat ini, AYO Kasir hanya | G39: Marcha | H39: Ida/Adnan | J39: 45930 | K39: Sprint 7 | N39: covered in sprint 7
A40: 33 | B40: AYO Kasir | D40: Voucher enhancement | E40: Voucher enhancement | F40: Voucher Product Limitation Adjustment | G40: Marcha | H40: Ida/Adnan | J40: 45930 | K40: Sprint 7 | N40: covered in sprint 7
...

Sheet MASTER SPRINT9
A1: Sprint List
A2: Objective : File ini digunakan oleh CI dan Deployment untuk mentracking List Sprint sepanjang tahun 2025
A3: User yang memiliki akses untuk edit adalah : Tim Deployment & CI
A4: Di isi yang warna biru
B5: New Sprint 9 | D5: Deprio Sprint 8 | F5: Lintas sprint from previous sprint (8) | H5: CI Sprint Proposed | I5: 0 | J5: lintas sprint dan harus masuk | Q5: SPRINT 9
C6: CI Team | G6: CI Team | L6: assume 1 sprint = 10 mandays | Q6: 45919 | R6: 45930 | S6: 45939 | T6: 45944 | U6: 45953 | V6: 45957 | W6: 45958
A7: No | B7: Platform (Aplikasi) | C7: Dependency | D7: Background | E7: Objective | F7: Description | G7: Product Manager | H7: Requestor | I7: Chanel | J7: Expected Deployed | K7: Sprint | L7: Rank Prio | M7: Re-Prio CI & Depl | N7: Sprint Carry Over | O7: Status | P7: Update 0 9/20 | Q7: Update 1 | R7: Update 2 | S7: Update 3 | T7: Update 4 | U7: Update 5 | V7: Update 6 | W7: Update 7 | X7: PRD | Y7: JIRA | Z7: Mandays | AA7: Remark
A8: 1 | B8: AMO Existing | D8: At this moment, there is no reference document available to confirm that the delivery of the CITA order via PG has indeed occurred, nor that it was delivered to the correct store. | E8: To provide a reliable mechanism for confirming and documenting the successful delivery of orders, ensuring accuracy, traceability, and accountability in the delivery process | F8: Proof of Delivery Feature: Unique code/ Taking photo | H8: Nastasya | J8: 45962 | K8: Sprint 9 | L8: 2 | M8: 7
A9: =A8+1 -> 2 | B9: AMO Existing | D9: Currently, the barcode scanning process does not yield any tangible benefits in terms of productivity for PG. Despite completing the scan, PGs still manually enter the relevant store visit information. | E9: Enhance operational efficiency by reducing manual input tasks for PG. Improve data accuracy by minimizing human error in store information entry. Accelerate visit preparation and allow PG to focus more on execution rather than administrative tasks. Ensure consistency in store data across all visits and reporting systems. | F9: This feature enables PGs to instantly retrieve store information upon scanning a barcode, eliminating the need for manual data entry. Once the barcode is scanned, relevant store details are automatically populated in the system interface. | H9: Nastasya | J9: 45962 | K9: Sprint 9 | L9: 1 | M9: 3
A10: =A9+1 -> 3 | B10: AYO KASIR | D10: Frontliners have inconsistent understanding of the complete product knowledge, talking points, and current programs or promotions. There are also limitations in accessing all supporting materials." | E10: Provide access for all frontliners to read and learn every working outlines, cue card and important initiatives | F10: Dedicated menu in AYO Kasir for WO/Program/Product Info/etc. library. Updateable through AYO Principle. | H10: IDA/Adnan | I10: SFP | J10: 45962 | K10: Sprint 10 | L10: 2 | M10: deprio
A11: =A10+1 -> 4 | B11: AYO KASIR | D11: Saat ini QRIS Dinamis BRI masih belum terintegrasi dengan AYO Kasir, sehingga transaksi melalui EDC BRI masih dilakukan terpisah dengan penginputan SO di AYO Kasir. Hal ini menyebabkan diperlukannya manual input approval code di AYO Kasir oleh frontliner dimana potensi human error sangat mungkin terjadi. Selain itu, missing input order juga dapat terjadi dikarenakan tidak adanya integrasi. | E11: 1. Mempermudah frontliner untuk melakukan transaksi dimana tidak perlu lagi penginputan approval code secara manual 2. Proses back-end reconciliation yang lebih efisien di tim OTC dikarenakan order tidak akan ter-create tanpa adanya payment 3. Meningkatkan jumlah transaksi menggunakan QRIS Dinamis BRI, dimana BRI menawarkan cashback rate yang tinggi untuk transaksi QRIS | F11: QRIS Dinamis BRI terintegrasi dengan AYO Kasir, sehingga order tidak akan ter-create tanpa adanya payment | H11: Linggajaya, Melissa/Ida | K11: Sprint 9 | M11: 6 | S11: In progress finalization
A12: =A11+1 -> 5 | B12: AYO Toko | D12: 1. Beberapa foto Toko (store outlook) di AYO Profile yang kurang menggambarkan situasi sebenarnya 2. Belum ada guide / standar yang tepat untuk memandu pemiliki Toko dalam pengisian Foto Toko di AYO Profile | E12: Untuk memvalidasi SRC Quality dan menggambarkan store outlook | F12: 1. Fitur image recognition 2. Fitur Video 3. Guide | H12: Dody | J12: Q1 2026 | K12: Sprint 9 | L12: 2 | M12: 2 | O12: Prio New Feature
A13: =A12+1 -> 6 | B13: AYO Toko | D13: 1. Belum ada pembeda antara SRC Quality dan SRC Regular didalam aplikasi AYO | E13: 1. Toko mengetahui statusnya sebagai SRC Quality 2. Toko mengetahui progress untuk menjadi SRC Quality | F13: SRC Quality Badge di AYO Toko | H13: Dody | J13: Q1 2026 | K13: Sprint 10 | M13: 4 | O13: Prio New Feature
A14: =A13+1 -> 7 | B14: AYO Toko | D14: 1. Belum ada menu untuk edukasi SFP di aplikasi AYO TOKO | E14: 1. Edukasi Toko SRC mengenai produk dan program SFP | F14: Edukasi SFP pada menu bebas Asap | H14: Kemal | J14: 46023 | K14: Sprint 9 | L14: 1 | M14: 1 | O14: Prio New Feature | AA14: injecting video/tutorial edukasi SFP di menu bebas asap
